<?xml version="1.0" encoding="utf-8"?>
<testsuites>
    <testsuite errors="0" failures="2" hostname="DESKTOP-NO52HB5" name="pytest" skipped="0" tests="5" time="0.357"
               timestamp="2020-08-13T09:29:56.198524">
        <testcase classname="test_cal.TestCalc" file="test_cal.py" line="15" name="test_add1" time="0.003"></testcase>
        <testcase classname="test_cal.TestCalc" file="test_cal.py" line="21" name="test_add2" time="0.002">
            <failure message="assert 12 == 11">self = &lt;pytest_test.SZ.testing.test_cal.TestCalc object at
                0x000001803EF6CE20&gt;

                @pytest.mark.add
                def test_add2(self):
                calc = Calculator()
                result = calc.add(1, 10)
                &gt; assert 12 == result
                E assert 12 == 11

                test_cal.py:26: AssertionError
            </failure>
        </testcase>
        <testcase classname="test_cal.TestCalc" file="test_cal.py" line="27" name="test_add3" time="0.002">
            <failure message="assert 102 == 101">self = &lt;pytest_test.SZ.testing.test_cal.TestCalc object at
                0x000001803EF8CA30&gt;

                @pytest.mark.add
                def test_add3(self):
                calc = Calculator()
                result = calc.add(100, 1)
                &gt; assert 102 == result
                E assert 102 == 101

                test_cal.py:32: AssertionError
            </failure>
        </testcase>
        <testcase classname="test_cal.TestCalc" file="test_cal.py" line="39" name="test_mul" time="0.000"></testcase>
        <testcase classname="test_cal.TestCalc" file="test_cal.py" line="45" name="test_div" time="0.002"></testcase>
    </testsuite>
</testsuites>